2021-05-28 16:03:43,140 ERROR: Exception on /reset_password_request [POST] [in /home/bitnami/aeocb/venv/lib/python3.8/site-packages/flask/app.py:1454]
Traceback (most recent call last):
  File "/home/bitnami/aeocb/venv/lib/python3.8/site-packages/flask/app.py", line 2070, in wsgi_app
    response = self.full_dispatch_request()
  File "/home/bitnami/aeocb/venv/lib/python3.8/site-packages/flask/app.py", line 1515, in full_dispatch_request
    rv = self.handle_user_exception(e)
  File "/home/bitnami/aeocb/venv/lib/python3.8/site-packages/flask/app.py", line 1513, in full_dispatch_request
    rv = self.dispatch_request()
  File "/home/bitnami/aeocb/venv/lib/python3.8/site-packages/flask/app.py", line 1499, in dispatch_request
    return self.ensure_sync(self.view_functions[rule.endpoint])(**req.view_args)
  File "/home/bitnami/aeocb/app/routes.py", line 86, in reset_password_request
    send_password_reset_email(user)
  File "/home/bitnami/aeocb/app/email.py", line 13, in send_password_reset_email
    sender=app.config['ADMINS'][0],
NameError: name 'app' is not defined
2021-05-28 16:04:27,418 INFO: Microblog startup [in /home/bitnami/aeocb/app/__init__.py:34]
2021-05-28 16:04:45,386 ERROR: Exception on /reset_password_request [POST] [in /home/bitnami/aeocb/venv/lib/python3.8/site-packages/flask/app.py:1454]
Traceback (most recent call last):
  File "/home/bitnami/aeocb/venv/lib/python3.8/site-packages/flask/app.py", line 2070, in wsgi_app
    response = self.full_dispatch_request()
  File "/home/bitnami/aeocb/venv/lib/python3.8/site-packages/flask/app.py", line 1515, in full_dispatch_request
    rv = self.handle_user_exception(e)
  File "/home/bitnami/aeocb/venv/lib/python3.8/site-packages/flask/app.py", line 1513, in full_dispatch_request
    rv = self.dispatch_request()
  File "/home/bitnami/aeocb/venv/lib/python3.8/site-packages/flask/app.py", line 1499, in dispatch_request
    return self.ensure_sync(self.view_functions[rule.endpoint])(**req.view_args)
  File "/home/bitnami/aeocb/app/routes.py", line 86, in reset_password_request
    send_password_reset_email(user)
  File "/home/bitnami/aeocb/app/email.py", line 15, in send_password_reset_email
    text_body=render_template('email/reset_password.txt',
NameError: name 'render_template' is not defined
2021-05-28 16:05:47,530 INFO: Microblog startup [in /home/bitnami/aeocb/app/__init__.py:34]
2021-05-28 16:06:05,584 ERROR: Exception on /reset_password_request [POST] [in /home/bitnami/aeocb/venv/lib/python3.8/site-packages/flask/app.py:1454]
Traceback (most recent call last):
  File "/home/bitnami/aeocb/venv/lib/python3.8/site-packages/flask/app.py", line 2070, in wsgi_app
    response = self.full_dispatch_request()
  File "/home/bitnami/aeocb/venv/lib/python3.8/site-packages/flask/app.py", line 1515, in full_dispatch_request
    rv = self.handle_user_exception(e)
  File "/home/bitnami/aeocb/venv/lib/python3.8/site-packages/flask/app.py", line 1513, in full_dispatch_request
    rv = self.dispatch_request()
  File "/home/bitnami/aeocb/venv/lib/python3.8/site-packages/flask/app.py", line 1499, in dispatch_request
    return self.ensure_sync(self.view_functions[rule.endpoint])(**req.view_args)
  File "/home/bitnami/aeocb/app/routes.py", line 86, in reset_password_request
    send_password_reset_email(user)
  File "/home/bitnami/aeocb/app/email.py", line 17, in send_password_reset_email
    text_body=render_template('email/reset_password.txt',
  File "/home/bitnami/aeocb/venv/lib/python3.8/site-packages/flask/templating.py", line 147, in render_template
    return _render(
  File "/home/bitnami/aeocb/venv/lib/python3.8/site-packages/flask/templating.py", line 128, in _render
    rv = template.render(context)
  File "/home/bitnami/aeocb/venv/lib/python3.8/site-packages/jinja2/environment.py", line 1304, in render
    self.environment.handle_exception()
  File "/home/bitnami/aeocb/venv/lib/python3.8/site-packages/jinja2/environment.py", line 925, in handle_exception
    raise rewrite_traceback_stack(source=source)
  File "/home/bitnami/aeocb/app/templates/email/reset_password.txt", line 5, in top-level template code
    {{ url_for('auth.reset_password', token=token, _external=True) }}
  File "/home/bitnami/aeocb/venv/lib/python3.8/site-packages/flask/helpers.py", line 338, in url_for
    return appctx.app.handle_url_build_error(error, endpoint, values)
  File "/home/bitnami/aeocb/venv/lib/python3.8/site-packages/flask/helpers.py", line 325, in url_for
    rv = url_adapter.build(
  File "/home/bitnami/aeocb/venv/lib/python3.8/site-packages/werkzeug/routing.py", line 2305, in build
    raise BuildError(endpoint, values, method, self)
werkzeug.routing.BuildError: Could not build url for endpoint 'auth.reset_password' with values ['token']. Did you mean 'reset_password' instead?
2021-05-28 16:09:33,657 INFO: Microblog startup [in /home/bitnami/aeocb/app/__init__.py:34]
2021-05-28 16:10:00,409 ERROR: Exception on /reset_password_request [POST] [in /home/bitnami/aeocb/venv/lib/python3.8/site-packages/flask/app.py:1454]
Traceback (most recent call last):
  File "/home/bitnami/aeocb/venv/lib/python3.8/site-packages/flask/app.py", line 2070, in wsgi_app
    response = self.full_dispatch_request()
  File "/home/bitnami/aeocb/venv/lib/python3.8/site-packages/flask/app.py", line 1515, in full_dispatch_request
    rv = self.handle_user_exception(e)
  File "/home/bitnami/aeocb/venv/lib/python3.8/site-packages/flask/app.py", line 1513, in full_dispatch_request
    rv = self.dispatch_request()
  File "/home/bitnami/aeocb/venv/lib/python3.8/site-packages/flask/app.py", line 1499, in dispatch_request
    return self.ensure_sync(self.view_functions[rule.endpoint])(**req.view_args)
  File "/home/bitnami/aeocb/app/routes.py", line 86, in reset_password_request
    send_password_reset_email(user)
  File "/home/bitnami/aeocb/app/email.py", line 14, in send_password_reset_email
    send_email('[Microblog] Reset Your Password',
  File "/home/bitnami/aeocb/app/email.py", line 10, in send_email
    mail.send(msg)
  File "/home/bitnami/aeocb/venv/lib/python3.8/site-packages/flask_mail.py", line 491, in send
    with self.connect() as connection:
  File "/home/bitnami/aeocb/venv/lib/python3.8/site-packages/flask_mail.py", line 144, in __enter__
    self.host = self.configure_host()
  File "/home/bitnami/aeocb/venv/lib/python3.8/site-packages/flask_mail.py", line 158, in configure_host
    host = smtplib.SMTP(self.mail.server, self.mail.port)
  File "/opt/bitnami/python/lib/python3.8/smtplib.py", line 255, in __init__
    (code, msg) = self.connect(host, port)
  File "/opt/bitnami/python/lib/python3.8/smtplib.py", line 341, in connect
    (code, msg) = self.getreply()
  File "/opt/bitnami/python/lib/python3.8/smtplib.py", line 398, in getreply
    raise SMTPServerDisconnected("Connection unexpectedly closed")
smtplib.SMTPServerDisconnected: Connection unexpectedly closed
2021-05-28 17:07:25,310 INFO: Microblog startup [in /home/bitnami/aeocb/app/__init__.py:34]
2021-05-28 17:07:45,883 ERROR: Exception on /reset_password_request [POST] [in /home/bitnami/aeocb/venv/lib/python3.8/site-packages/flask/app.py:1454]
Traceback (most recent call last):
  File "/home/bitnami/aeocb/venv/lib/python3.8/site-packages/flask/app.py", line 2070, in wsgi_app
    response = self.full_dispatch_request()
  File "/home/bitnami/aeocb/venv/lib/python3.8/site-packages/flask/app.py", line 1515, in full_dispatch_request
    rv = self.handle_user_exception(e)
  File "/home/bitnami/aeocb/venv/lib/python3.8/site-packages/flask/app.py", line 1513, in full_dispatch_request
    rv = self.dispatch_request()
  File "/home/bitnami/aeocb/venv/lib/python3.8/site-packages/flask/app.py", line 1499, in dispatch_request
    return self.ensure_sync(self.view_functions[rule.endpoint])(**req.view_args)
  File "/home/bitnami/aeocb/app/routes.py", line 86, in reset_password_request
    send_password_reset_email(user)
  File "/home/bitnami/aeocb/app/email.py", line 14, in send_password_reset_email
    send_email('[Microblog] Reset Your Password',
  File "/home/bitnami/aeocb/app/email.py", line 10, in send_email
    mail.send(msg)
  File "/home/bitnami/aeocb/venv/lib/python3.8/site-packages/flask_mail.py", line 491, in send
    with self.connect() as connection:
  File "/home/bitnami/aeocb/venv/lib/python3.8/site-packages/flask_mail.py", line 144, in __enter__
    self.host = self.configure_host()
  File "/home/bitnami/aeocb/venv/lib/python3.8/site-packages/flask_mail.py", line 158, in configure_host
    host = smtplib.SMTP(self.mail.server, self.mail.port)
  File "/opt/bitnami/python/lib/python3.8/smtplib.py", line 255, in __init__
    (code, msg) = self.connect(host, port)
  File "/opt/bitnami/python/lib/python3.8/smtplib.py", line 341, in connect
    (code, msg) = self.getreply()
  File "/opt/bitnami/python/lib/python3.8/smtplib.py", line 398, in getreply
    raise SMTPServerDisconnected("Connection unexpectedly closed")
smtplib.SMTPServerDisconnected: Connection unexpectedly closed
2021-05-28 17:09:16,149 INFO: Microblog startup [in /home/bitnami/aeocb/app/__init__.py:34]
